<mujoco model="phantom_limb">
    <option timestep=".001"/>

    <compiler angle="radian" strippath="true" meshdir="meshes/"/>

    <extension>
        <plugin plugin="mujoco.elasticity.solid"/>
    </extension>

    <asset>
        <material name="mat_bones" rgba="0.2 0.2 0.2 1"/>

        <mesh file="l_pelvis_phantom.stl" name="l_pelvis"/>
        <mesh file="l_femur_phantom.stl" name="l_femur"/>
        <mesh file="l_tibia_phantom.stl" name="l_tibia"/>
        <mesh file="l_foot_phantom.stl" name="l_foot"/>
        <!-- <mesh file="decomp.stl" name="l_thigh_band"/> -->
        <mesh file="l_thigh_band000.obj" name="l_thigh_band000"/>
        <mesh file="l_thigh_band001.obj" name="l_thigh_band001"/>
        <mesh file="l_thigh_band002.obj" name="l_thigh_band002"/>
        <mesh file="l_thigh_band003.obj" name="l_thigh_band003"/>
        <mesh file="l_thigh_band004.obj" name="l_thigh_band004"/>
        <mesh file="l_thigh_band005.obj" name="l_thigh_band005"/>
        <mesh file="l_thigh_band006.obj" name="l_thigh_band006"/>
        <mesh file="l_thigh_band007.obj" name="l_thigh_band007"/>
        <mesh file="l_thigh_band008.obj" name="l_thigh_band008"/>
        <mesh file="l_thigh_band009.obj" name="l_thigh_band009"/>
        <mesh file="platform.stl" name="platform"/>
    </asset>

    <default>
        <default class="bones">
            <joint armature="0.01" damping="0.5" limited="true"/>
            <geom margin="0.001" material="mat_bones" conaffinity="0" contype="0"/>
        </default>
        <default class="exosuit">
            <geom conaffinity="1" contype="1"/>
        </default>
        <default class="flexbody">
            <joint armature="0" damping="0" limited="false"/>
        </default>
    </default>

    <actuator>
        <position name="platform_act" kp="10000" kv="1000" joint="platform_slide" ctrllimited="true" ctrlrange="0.0175 0.215"/>
    </actuator>

    <equality>
        <weld body1="foot_l" body2="platform"/>
    </equality>

    <sensor>
        <force name="ankle_force" site="ankle_sensor"/>
    </sensor>

    <worldbody>
        <body name="platform" pos="-0.065 0.075 0.06" childclass="bones">
            <joint type="slide" axis="0 0 1" name="platform_slide" range="-0.5 0.5"/>
            <geom mesh="platform" name="platform" type="mesh" mass="1" quat="0.707107 0.707107 0 0"/>
        </body>

        <body name="pelvis" pos="0 0 1" quat="0.707107 0.707107 0 0" childclass="bones">
            <inertial pos="-0.07 -0.03 0" mass="10.96" diaginertia="0.0622075 0.0532711 0.0299242" />
            <geom mesh="l_pelvis" name="l_pelvis" type="mesh"/>

            <body name="femur_l" pos="-0.056276 -0.07849 -0.07726">
                <inertial pos="0 -0.195 0.0005" quat="0.7062 -0.708013 0 0" mass="0.3" diaginertia="0.1694 0.1694 0.0245269" />
                <joint axis="0 0 1" name="hip_flexion_l" pos="0 0 0" range="-0.523599 2.0944"/>
                <geom mesh="l_femur" name="l_femur" type="mesh"/>

                <body name="thigh_l" pos="0 0 0" childclass="flexbody">
                    <flexcomp type="gmsh" file="l_thigh.msh" radius="0.001" rgba=".9 .7 .0 .3" name="l_thigh" dim="2" mass="8.1">
                        <contact condim="3" solref="0.01 1" solimp=".95 .99 .0001" selfcollide="none"/>
                        <edge damping="1"/>
                        <plugin plugin="mujoco.elasticity.solid">
                            <config key="poisson" value="0.25"/>
                            <config key="young" value="5e4"/>
                        </plugin>
                        <pin id="41"/>
                        <pin id="52"/>
                        <pin id="58"/>
                        <pin id="48"/>
                        <pin id="68"/>
                        <pin id="215"/>
                        <pin id="188"/>
                        <pin id="59"/>
                        <pin id="84"/>
                        <pin id="45"/>
                        <pin id="50"/>
                        <pin id="56"/>
                        <pin id="224"/>
                        <pin id="204"/>
                        <pin id="57"/>
                        <pin id="70"/>
                        <pin id="169"/>
                        <pin id="196"/>
                        <pin id="209"/>
                        <pin id="197"/>
                        <pin id="60"/>
                        <pin id="189"/>
                        <pin id="228"/>
                        <pin id="85"/>
                        <pin id="227"/>
                        <pin id="208"/>
                        <pin id="71"/>
                        <pin id="76"/>
                        <pin id="203"/>
                        <pin id="184"/>
                        <pin id="199"/>
                        <pin id="73"/>
                        <pin id="202"/>
                        <pin id="93"/>
                        <pin id="187"/>
                        <pin id="216"/>
                        <pin id="192"/>
                        <pin id="205"/>
                        <pin id="210"/>
                        <pin id="218"/>
                        <pin id="96"/>
                        <pin id="217"/>
                        <pin id="89"/>
                        <pin id="81"/>
                        <pin id="88"/>
                        <pin id="79"/>
                        <pin id="211"/>
                        <pin id="99"/>
                        <pin id="222"/>
                        <pin id="201"/>
                        <pin id="220"/>
                        <pin id="95"/>
                        <pin id="219"/>
                        <pin id="77"/>
                        <pin id="175"/>
                        <pin id="178"/>
                        <pin id="82"/>
                        <pin id="97"/>
                        <pin id="91"/>
                        <pin id="206"/>
                        <pin id="194"/>
                        <pin id="94"/>
                        <pin id="80"/>
                        <pin id="83"/>
                        <pin id="69"/>
                    </flexcomp>
                </body>

                <body name="thigh_band_l" pos="0 0 0" childclass="exosuit">
                    <joint axis="0 0 1" name="thigh_band_knee" pos="-4.6e-07 -0.404425 0.00126526"/>
                    <!-- <geom mesh="l_thigh_band" name="l_thigh_band" type="mesh"/> -->
                    <geom mesh="l_thigh_band000" type="mesh"/>
                    <geom mesh="l_thigh_band001" type="mesh"/>
                    <geom mesh="l_thigh_band002" type="mesh"/>
                    <geom mesh="l_thigh_band003" type="mesh"/>
                    <geom mesh="l_thigh_band004" type="mesh"/>
                    <geom mesh="l_thigh_band005" type="mesh"/>
                    <geom mesh="l_thigh_band006" type="mesh"/>
                    <geom mesh="l_thigh_band007" type="mesh"/>
                    <geom mesh="l_thigh_band008" type="mesh"/>
                    <geom mesh="l_thigh_band009" type="mesh"/>
                </body>

                <body name="tibia_l" pos="-4.6e-07 -0.404425 0.00126526">
                    <inertial pos="-0.005 -0.175 -0.0025" quat="0.712137 -0.701754 0.0200501 0" mass="3.8" diaginertia="0.0771589 0.0771589 0.00690387" />
                    <joint axis="0 0 -1" name="knee_angle_l" pos="0 0 0" range="0 2.0944"/>
                    <geom mesh="l_tibia" name="l_tibia" type="mesh"/>

                    <body name="shank_l" pos="0 0 0" childclass="flexbody">
                        <flexcomp type="gmsh" file="l_shank.msh" radius="0.001" rgba=".9 .7 .0 .3" name="l_shank" dim="2" mass="8.1">
                            <contact condim="3" solref="0.01 1" solimp=".95 .99 .0001" selfcollide="none"/>
                            <edge damping="1"/>
                            <plugin plugin="mujoco.elasticity.solid">
                                <config key="poisson" value="0.25"/>
                                <config key="young" value="5e4"/>
                            </plugin>
                            <pin id="76"/>
                            <pin id="90"/>
                            <pin id="65"/>
                            <pin id="64"/>
                            <pin id="200"/>
                            <pin id="74"/>
                            <pin id="85"/>
                            <pin id="109"/>
                            <pin id="100"/>
                            <pin id="117"/>
                            <pin id="243"/>
                            <pin id="169"/>
                            <pin id="164"/>
                            <pin id="146"/>
                            <pin id="98"/>
                            <pin id="213"/>
                            <pin id="92"/>
                            <pin id="79"/>
                            <pin id="73"/>
                            <pin id="97"/>
                            <pin id="89"/>
                            <pin id="75"/>
                            <pin id="235"/>
                            <pin id="196"/>
                            <pin id="230"/>
                            <pin id="91"/>
                            <pin id="228"/>
                            <pin id="236"/>
                            <pin id="237"/>
                            <pin id="253"/>
                            <pin id="234"/>
                            <pin id="263"/>
                            <pin id="82"/>
                            <pin id="197"/>
                            <pin id="254"/>
                            <pin id="227"/>
                            <pin id="233"/>
                            <pin id="247"/>
                            <pin id="88"/>
                            <pin id="70"/>
                            <pin id="255"/>
                            <pin id="69"/>
                            <pin id="211"/>
                            <pin id="225"/>
                            <pin id="216"/>
                            <pin id="212"/>
                            <pin id="203"/>
                            <pin id="239"/>
                            <pin id="238"/>
                            <pin id="259"/>
                            <pin id="80"/>
                            <pin id="220"/>
                            <pin id="95"/>
                            <pin id="246"/>
                            <pin id="265"/>
                            <pin id="260"/>
                            <pin id="204"/>
                            <pin id="226"/>
                            <pin id="219"/>
                            <pin id="208"/>
                            <pin id="205"/>
                            <pin id="207"/>
                            <pin id="210"/>
                            <pin id="96"/>
                            <pin id="78"/>
                            <pin id="77"/>
                            <pin id="86"/>
                            <pin id="102"/>
                            <pin id="121"/>
                            <pin id="115"/>
                            <pin id="108"/>
                            <pin id="156"/>
                            <pin id="158"/>
                            <pin id="214"/>
                            <pin id="140"/>
                            <pin id="159"/>
                            <pin id="206"/>
                            <pin id="116"/>
                            <pin id="113"/>
                            <pin id="160"/>
                            <pin id="137"/>
                            <pin id="264"/>
                            <pin id="122"/>
                            <pin id="157"/>
                            <pin id="241"/>
                            <pin id="240"/>
                            <pin id="118"/>
                            <pin id="143"/>
                            <pin id="252"/>
                            <pin id="248"/>
                            <pin id="145"/>
                            <pin id="123"/>
                            <pin id="256"/>
                            <pin id="130"/>
                            <pin id="251"/>
                            <pin id="154"/>
                            <pin id="129"/>
                            <pin id="232"/>
                            <pin id="141"/>
                            <pin id="222"/>
                            <pin id="221"/>
                            <pin id="223"/>
                            <pin id="231"/>
                            <pin id="202"/>
                            <pin id="257"/>
                            <pin id="258"/>
                            <pin id="114"/>
                            <pin id="112"/>
                            <pin id="195"/>
                            <pin id="136"/>
                            <pin id="224"/>
                            <pin id="147"/>
                            <pin id="110"/>
                            <pin id="217"/>
                            <pin id="111"/>
                            <pin id="125"/>
                            <pin id="134"/>
                            <pin id="144"/>
                            <pin id="131"/>
                        </flexcomp>
                    </body>

                    <body name="foot_l" pos="-0.01 -0.4 0">
                        <joint axis="0 0 1" name="ankle_angle_l" pos="0 0 0" range="-0.9 0.9"/>
                        <geom mesh="l_foot" name="l_foot" type="mesh"/>
                        <site name="ankle_sensor" pos="0 0 0"/>
                    </body>
                </body>
            </body>
        </body>

        <geom name="ground" type="plane" pos="0 0 0" size="5 5 0.1" rgba="0.8 0.8 0.8 1"/>
    </worldbody>
</mujoco>