<mujoco model="phantom_barrutia">
    <option timestep=".001"/>

    <compiler angle="radian" strippath="true" meshdir="meshes/Barrutia/"/>

    <visual>
        <map force="0.001"/>
        <scale framelength="0.1" framewidth="0.01"/>
    </visual>

    <asset>
        <texture name="skybox" type="skybox" builtin="flat" rgb1="0.8 0.8 0.8" rgb2="0.8 0.8 0.8" width="512" height="512"/>

        <material name="mat_bones" rgba="0.2 0.2 0.2 1"/>
        <material name="exosuit" rgba="0.2 0.2 0.2 1"/>

        <mesh file="Hip Fixture.STL" name="hip_fixture"/>
        <mesh file="Femur.STL" name="femur"/>
        <mesh file="Tibia.STL" name="tibia"/>
        <mesh file="Foot.STL" name="foot"/>
        <mesh file="Platform.STL" name="platform"/>
    </asset>

    <default>
        <default class="bones">
            <joint armature="0.01" damping="0.5" limited="true"/>
            <geom margin="0.001" material="mat_bones" conaffinity="0" contype="0"/>
        </default>
        <default class="exosuit">
            <geom conaffinity="1" contype="1" material="exosuit"/>
        </default>
        <default class="flexbody">
            <joint armature="0" damping="0" limited="false"/>
        </default>
    </default>

    <equality>
        <weld body1="foot" body2="platform" torquescale="1000"/>
    </equality>

    <sensor>
        <force name="ankle_force" site="ankle_sensor"/>
    </sensor>

    <worldbody>
        <body name="platform" pos="0 0 0" childclass="bones" mocap="true">
            <geom mesh="platform" name="platform" type="mesh" mass="1" pos="0.03835 0.07698 0" quat="0.707107 0.707107 0 0"/>
        </body>

        <body name="hip_fixture" pos="0 0 0" childclass="bones">
            <inertial pos="-0.07 -0.03 0" mass="10.96" diaginertia="0.0622075 0.0532711 0.0299242" />
            <geom mesh="hip_fixture" name="hip_fixture" type="mesh"/>

            <body name="femur" pos="0.03835 0.07698 0.65793">
                <inertial pos="0 -0.195 0.0005" quat="0.7062 -0.708013 0 0" mass="0.3" diaginertia="0.1694 0.1694 0.0245269" />
                <joint axis="0 1 0" name="hip_flexion_l" pos="0 0 0" range="-0.523599 2.0944"/>
                <geom mesh="femur" name="femur" type="mesh"/>

                <body name="thigh" pos="0 0 0" childclass="flexbody">
                    <flexcomp type="gmsh" file="Thigh.msh" radius="0.001" rgba=".9 .7 .0 .3" name="thigh" dim="2" mass="8.1">
                        <contact condim="3" solref="0.01 1" solimp=".95 .99 .0001" selfcollide="none"/>
                        <edge damping="1"/>
                        <elasticity young="5e4" poisson="0.25"/>
                        <pin id="41"/>
                        <pin id="52"/>
                        <pin id="58"/>
                        <pin id="48"/>
                        <pin id="68"/>
                        <pin id="215"/>
                        <pin id="188"/>
                        <pin id="59"/>
                        <pin id="84"/>
                        <pin id="45"/>
                        <pin id="50"/>
                        <pin id="56"/>
                        <pin id="224"/>
                        <pin id="204"/>
                        <pin id="57"/>
                        <pin id="70"/>
                        <pin id="169"/>
                        <pin id="196"/>
                        <pin id="209"/>
                        <pin id="197"/>
                        <pin id="60"/>
                        <pin id="189"/>
                        <pin id="228"/>
                        <pin id="85"/>
                        <pin id="227"/>
                        <pin id="208"/>
                        <pin id="71"/>
                        <pin id="76"/>
                        <pin id="203"/>
                        <pin id="184"/>
                        <pin id="199"/>
                        <pin id="73"/>
                        <pin id="202"/>
                        <pin id="93"/>
                        <pin id="187"/>
                        <pin id="216"/>
                        <pin id="192"/>
                        <pin id="205"/>
                        <pin id="210"/>
                        <pin id="218"/>
                        <pin id="96"/>
                        <pin id="217"/>
                        <pin id="89"/>
                        <pin id="81"/>
                        <pin id="88"/>
                        <pin id="79"/>
                        <pin id="211"/>
                        <pin id="99"/>
                        <pin id="222"/>
                        <pin id="201"/>
                        <pin id="220"/>
                        <pin id="95"/>
                        <pin id="219"/>
                        <pin id="77"/>
                        <pin id="175"/>
                        <pin id="178"/>
                        <pin id="82"/>
                        <pin id="97"/>
                        <pin id="91"/>
                        <pin id="206"/>
                        <pin id="194"/>
                        <pin id="94"/>
                        <pin id="80"/>
                        <pin id="83"/>
                        <pin id="69"/>
                    </flexcomp>
                </body>

                <body name="tibia" pos="-0.00526 0 -0.29865">
                    <inertial pos="-0.005 -0.175 -0.0025" quat="0.712137 -0.701754 0.0200501 0" mass="3.8" diaginertia="0.0771589 0.0771589 0.00690387" />
                    <joint axis="0 1 0" name="knee_angle_l" pos="0 0 0" range="0 2.0944"/>
                    <geom mesh="tibia" name="tibia" type="mesh"/>

                    <body name="shank" pos="0 0 0" childclass="flexbody">
                        <flexcomp type="gmsh" file="Shank.msh" radius="0.001" rgba=".9 .7 .0 .3" name="l_shank" dim="2" mass="8.1">
                            <contact condim="3" solref="0.01 1" solimp=".95 .99 .0001" selfcollide="none"/>
                            <edge damping="1"/>
                            <elasticity young="5e4" poisson="0.25"/>
                            <pin id="76"/>
                            <pin id="90"/>
                            <pin id="65"/>
                            <pin id="64"/>
                            <pin id="200"/>
                            <pin id="74"/>
                            <pin id="85"/>
                            <pin id="109"/>
                            <pin id="100"/>
                            <pin id="117"/>
                            <pin id="243"/>
                            <pin id="169"/>
                            <pin id="164"/>
                            <pin id="146"/>
                            <pin id="98"/>
                            <pin id="213"/>
                            <pin id="92"/>
                            <pin id="79"/>
                            <pin id="73"/>
                            <pin id="97"/>
                            <pin id="89"/>
                            <pin id="75"/>
                            <pin id="235"/>
                            <pin id="196"/>
                            <pin id="230"/>
                            <pin id="91"/>
                            <pin id="228"/>
                            <pin id="236"/>
                            <pin id="237"/>
                            <pin id="253"/>
                            <pin id="234"/>
                            <pin id="263"/>
                            <pin id="82"/>
                            <pin id="197"/>
                            <pin id="254"/>
                            <pin id="227"/>
                            <pin id="233"/>
                            <pin id="247"/>
                            <pin id="88"/>
                            <pin id="70"/>
                            <pin id="255"/>
                            <pin id="69"/>
                            <pin id="211"/>
                            <pin id="225"/>
                            <pin id="216"/>
                            <pin id="212"/>
                            <pin id="203"/>
                            <pin id="239"/>
                            <pin id="238"/>
                            <pin id="259"/>
                            <pin id="80"/>
                            <pin id="220"/>
                            <pin id="95"/>
                            <pin id="246"/>
                            <pin id="265"/>
                            <pin id="260"/>
                            <pin id="204"/>
                            <pin id="226"/>
                            <pin id="219"/>
                            <pin id="208"/>
                            <pin id="205"/>
                            <pin id="207"/>
                            <pin id="210"/>
                            <pin id="96"/>
                            <pin id="78"/>
                            <pin id="77"/>
                            <pin id="86"/>
                            <pin id="102"/>
                            <pin id="121"/>
                            <pin id="115"/>
                            <pin id="108"/>
                            <pin id="156"/>
                            <pin id="158"/>
                            <pin id="214"/>
                            <pin id="140"/>
                            <pin id="159"/>
                            <pin id="206"/>
                            <pin id="116"/>
                            <pin id="113"/>
                            <pin id="160"/>
                            <pin id="137"/>
                            <pin id="264"/>
                            <pin id="122"/>
                            <pin id="157"/>
                            <pin id="241"/>
                            <pin id="240"/>
                            <pin id="118"/>
                            <pin id="143"/>
                            <pin id="252"/>
                            <pin id="248"/>
                            <pin id="145"/>
                            <pin id="123"/>
                            <pin id="256"/>
                            <pin id="130"/>
                            <pin id="251"/>
                            <pin id="154"/>
                            <pin id="129"/>
                            <pin id="232"/>
                            <pin id="141"/>
                            <pin id="222"/>
                            <pin id="221"/>
                            <pin id="223"/>
                            <pin id="231"/>
                            <pin id="202"/>
                            <pin id="257"/>
                            <pin id="258"/>
                            <pin id="114"/>
                            <pin id="112"/>
                            <pin id="195"/>
                            <pin id="136"/>
                            <pin id="224"/>
                            <pin id="147"/>
                            <pin id="110"/>
                            <pin id="217"/>
                            <pin id="111"/>
                            <pin id="125"/>
                            <pin id="134"/>
                            <pin id="144"/>
                            <pin id="131"/>
                        </flexcomp>
                    </body>

                    <body name="foot" pos="-0.00526 0 -0.30429">
                        <joint axis="0 1 0" name="ankle_angle_l" pos="0 0 0" range="-0.9 0.9"/>
                        <geom mesh="foot" name="foot" type="mesh"/>
                        <site name="ankle_sensor" pos="0 0 0"/>
                    </body>
                </body>
            </body>
        </body>
    </worldbody>
</mujoco>