<mujoco model="phantom_barrutia">
    <option timestep=".001"/>

    <compiler angle="radian" strippath="true" meshdir="meshes/Barrutia/"/>

    <visual>
        <map force="0.001"/>
        <scale framelength="0.1" framewidth="0.01"/>
    </visual>

    <asset>
        <texture name="skybox" type="skybox" builtin="flat" rgb1="0.8 0.8 0.8" rgb2="0.8 0.8 0.8" width="512" height="512"/>

        <material name="mat_bones" rgba="0.2 0.2 0.2 1"/>
        <material name="exosuit" rgba="0.2 0.2 0.2 1"/>

        <mesh file="Hip Fixture.STL" name="hip_fixture"/>
        <mesh file="Femur.STL" name="femur"/>
        <mesh file="Tibia.STL" name="tibia"/>
        <mesh file="Foot.STL" name="foot"/>
        <mesh file="Platform.STL" name="platform"/>
    </asset>

    <default>
        <default class="bones">
            <joint armature="0.01" damping="0.5" limited="true"/>
            <geom margin="0.001" material="mat_bones" conaffinity="0" contype="0"/>
        </default>
        <default class="exosuit">
            <geom conaffinity="1" contype="1" material="exosuit"/>
        </default>
        <default class="flexbody">
            <joint armature="0" damping="0" limited="false"/>
        </default>
    </default>

    <equality>
        <weld body1="foot" body2="platform" torquescale="1000"/>
    </equality>

    <sensor>
        <force name="ankle_force" site="ankle_sensor"/>
    </sensor>

    <worldbody>
        <body name="platform" pos="0 0 0" childclass="bones" mocap="true">
            <geom mesh="platform" name="platform" type="mesh" mass="1" pos="0.03835 0.07698 0" quat="0.707107 0.707107 0 0"/>
        </body>

        <body name="hip_fixture" pos="0 0 0" childclass="bones">
            <inertial pos="0.03835 0.07698 0.67989" mass="0.13071" diaginertia="0.00006778 0.00006167 0.00008403" />
            <geom mesh="hip_fixture" name="hip_fixture" type="mesh"/>

            <body name="femur" pos="0.03835 0.07698 0.65793">
                <inertial pos="0.00457 0.01134 -0.14377" mass="0.24064" xyaxes="-0.11102 0.06309 0.99181 -0.33501 0.93720 -0.09711" diaginertia="0.00005 0.00247 0.00248"/>
                <joint axis="0 1 0" name="hip_flexion_l" pos="0 0 0" range="-0.523599 2.0944"/>
                <geom mesh="femur" name="femur" type="mesh"/>

                <body name="thigh" pos="0 0 0" childclass="flexbody">
                    <flexcomp type="gmsh" file="Thigh.msh" rgba=".9 .7 .0 .3" name="thigh" dim="2" mass="22.6449451">
                        <contact condim="3" solref="0.01 1" solimp=".95 .99 .0001" selfcollide="none"/>
                        <edge damping="1"/>
                        <elasticity young="5e4" poisson="0.25"/>
                        <!-- <elasticity young="6.6e4" poisson="0.48" damping="2.5e-5"/> -->
                        <pin id="56"/>
                        <pin id="43"/>
                        <pin id="30"/>
                        <pin id="73"/>
                        <pin id="45"/>
                        <pin id="81"/>
                        <pin id="24"/>
                        <pin id="41"/>
                        <pin id="27"/>
                        <pin id="29"/>
                        <pin id="36"/>
                        <pin id="83"/>
                        <pin id="91"/>
                        <pin id="93"/>
                        <pin id="63"/>
                        <pin id="28"/>
                        <pin id="49"/>
                        <pin id="35"/>
                        <pin id="87"/>
                        <pin id="96"/>
                        <pin id="86"/>
                        <pin id="97"/>
                        <pin id="311"/>
                        <pin id="114"/>
                        <pin id="102"/>
                        <pin id="162"/>
                        <pin id="32"/>
                        <pin id="33"/>
                        <pin id="39"/>
                        <pin id="46"/>
                        <pin id="47"/>
                        <pin id="37"/>
                        <pin id="53"/>
                        <pin id="51"/>
                        <pin id="69"/>
                        <pin id="92"/>
                        <pin id="121"/>
                        <pin id="113"/>
                        <pin id="125"/>
                        <pin id="84"/>
                        <pin id="108"/>
                        <pin id="163"/>
                        <pin id="319"/>
                        <pin id="52"/>
                        <pin id="48"/>
                        <pin id="74"/>
                        <pin id="110"/>
                        <pin id="55"/>
                        <pin id="80"/>
                        <pin id="67"/>
                        <pin id="66"/>
                        <pin id="124"/>
                        <pin id="79"/>
                        <pin id="148"/>
                        <pin id="132"/>
                        <pin id="189"/>
                        <pin id="77"/>
                        <pin id="82"/>
                        <pin id="348"/>
                        <pin id="90"/>
                        <pin id="100"/>
                        <pin id="342"/>
                        <pin id="204"/>
                        <pin id="101"/>
                        <pin id="168"/>
                        <pin id="155"/>
                        <pin id="209"/>
                        <pin id="182"/>
                        <pin id="106"/>
                        <pin id="112"/>
                        <pin id="140"/>
                        <pin id="115"/>
                        <pin id="213"/>
                        <pin id="126"/>
                        <pin id="160"/>
                        <pin id="136"/>
                        <pin id="175"/>
                        <pin id="159"/>
                        <pin id="361"/>
                        <pin id="145"/>
                        <pin id="153"/>
                        <pin id="214"/>
                        <pin id="171"/>
                        <pin id="202"/>
                        <pin id="135"/>
                        <pin id="119"/>
                        <pin id="99"/>
                        <pin id="109"/>
                        <pin id="103"/>
                        <pin id="122"/>
                        <pin id="126"/>
                        <pin id="89"/>
                        <pin id="184"/>
                        <pin id="218"/>
                        <pin id="212"/>
                        <pin id="241"/>
                        <pin id="354"/>
                        <pin id="238"/>
                        <pin id="193"/>
                        <pin id="226"/>
                        <pin id="341"/>
                        <pin id="62"/>
                        <pin id="164"/>
                        <pin id="76"/>
                        <pin id="118"/>
                        <pin id="58"/>
                        <pin id="71"/>
                        <pin id="177"/>
                        <pin id="149"/>
                        <pin id="165"/>
                        <pin id="117"/>
                        <pin id="178"/>
                        <pin id="151"/>
                        <pin id="321"/>
                        <pin id="116"/>
                        <pin id="324"/>
                        <pin id="167"/>
                        <pin id="168"/>
                        <pin id="166"/>
                        <pin id="173"/>
                        <pin id="200"/>
                        <pin id="227"/>
                        <pin id="210"/>
                        <pin id="181"/>
                        <pin id="123"/>
                        <pin id="146"/>
                        <pin id="239"/>
                        <pin id="194"/>
                        <pin id="127"/>
                        <pin id="143"/>
                        <pin id="176"/>
                        <pin id="215"/>
                        <pin id="211"/>
                        <pin id="111"/>
                        <pin id="142"/>
                        <pin id="179"/>
                        <pin id="172"/>
                        <pin id="180"/>
                        <pin id="152"/>
                        <pin id="188"/>
                        <pin id="195"/>
                        <pin id="185"/>
                        <pin id="203"/>
                        <pin id="207"/>
                        <pin id="221"/>
                        <pin id="216"/>
                        <pin id="219"/>
                        <pin id="228"/>
                        <pin id="328"/>
                        <pin id="235"/>
                        <pin id="231"/>
                        <pin id="183"/>
                        <pin id="230"/>
                        <pin id="234"/>
                        <pin id="232"/>
                        <pin id="220"/>
                        <pin id="243"/>
                        <pin id="201"/>
                        <pin id="242"/>
                        <pin id="256"/>
                        <pin id="242"/>
                        <pin id="240"/>
                        <pin id="217"/>
                        <pin id="249"/>
                        <pin id="252"/>
                        <pin id="254"/>
                        <pin id="244"/>
                        <pin id="257"/>
                        <pin id="260"/>
                        <pin id="262"/>
                        <pin id="253"/>
                        <pin id="258"/>
                        <pin id="266"/>
                        <pin id="265"/>
                        <pin id="268"/>
                        <pin id="246"/>
                        <pin id="264"/>
                        <pin id="272"/>
                        <pin id="251"/>
                        <pin id="269"/>
                        <pin id="318"/>
                        <pin id="273"/>
                        <pin id="271"/>
                        <pin id="186"/>
                        <pin id="245"/>
                    </flexcomp>
                </body>

                <body name="tibia" pos="-0.00526 0 -0.29865">
                    <inertial pos="0.00158 0.00259 -0.10784" mass="0.32564" fullinertia="0.00298 0.00298 0.00010 -0.00001 0.00012 -0.00001"/>
                    <joint axis="0 1 0" name="knee_angle_l" pos="0 0 0" range="0 2.0944"/>
                    <geom mesh="tibia" name="tibia" type="mesh"/>

                    <body name="shank" pos="0 0 0" childclass="flexbody">
                        <flexcomp type="gmsh" file="Shank.msh" rgba=".9 .7 .0 .3" name="l_shank" dim="2" mass="9.0204033">
                            <contact condim="3" solref="0.01 1" solimp=".95 .99 .0001" selfcollide="none"/>
                            <edge damping="1"/>
                            <elasticity young="5e4" poisson="0.25"/>
                            <!-- <elasticity young="6.6e4" poisson="0.48" damping="2.5e-5"/> -->
                            <pin id="148"/>
                            <pin id="100"/>
                            <pin id="134"/>
                            <pin id="139"/>
                            <pin id="165"/>
                            <pin id="178"/>
                            <pin id="221"/>
                            <pin id="177"/>
                            <pin id="158"/>
                            <pin id="164"/>
                            <pin id="211"/>
                            <pin id="174"/>
                            <pin id="208"/>
                            <pin id="253"/>
                            <pin id="172"/>
                            <pin id="189"/>
                            <pin id="163"/>
                            <pin id="176"/>
                            <pin id="209"/>
                            <pin id="187"/>
                            <pin id="143"/>
                            <pin id="195"/>
                            <pin id="192"/>
                            <pin id="150"/>
                            <pin id="155"/>
                            <pin id="145"/>
                            <pin id="181"/>
                            <pin id="133"/>
                            <pin id="160"/>
                            <pin id="212"/>
                            <pin id="130"/>
                            <pin id="220"/>
                            <pin id="220"/>
                            <pin id="218"/>
                            <pin id="166"/>
                            <pin id="128"/>
                            <pin id="122"/>
                            <pin id="101"/>
                            <pin id="88"/>
                            <pin id="135"/>
                            <pin id="183"/>
                            <pin id="245"/>
                            <pin id="120"/>
                            <pin id="151"/>
                            <pin id="273"/>
                            <pin id="201"/>
                            <pin id="258"/>
                            <pin id="222"/>
                            <pin id="272"/>
                            <pin id="162"/>
                            <pin id="275"/>
                            <pin id="268"/>
                            <pin id="263"/>
                            <pin id="259"/>
                            <pin id="264"/>
                            <pin id="250"/>
                            <pin id="260"/>
                            <pin id="225"/>
                            <pin id="257"/>
                            <pin id="256"/>
                            <pin id="235"/>
                            <pin id="238"/>
                            <pin id="252"/>
                            <pin id="240"/>
                            <pin id="247"/>
                            <pin id="227"/>
                            <pin id="241"/>
                            <pin id="236"/>
                            <pin id="210"/>
                            <pin id="228"/>
                            <pin id="244"/>
                            <pin id="233"/>
                            <pin id="249"/>
                            <pin id="248"/>
                            <pin id="196"/>
                            <pin id="289"/>
                            <pin id="291"/>
                            <pin id="317"/>
                            <pin id="290"/>
                            <pin id="282"/>
                            <pin id="270"/>
                            <pin id="285"/>
                            <pin id="271"/>
                            <pin id="284"/>
                            <pin id="276"/>
                            <pin id="185"/>
                            <pin id="333"/>
                            <pin id="265"/>
                            <pin id="182"/>
                            <pin id="190"/>
                            <pin id="261"/>
                            <pin id="167"/>
                            <pin id="180"/>
                            <pin id="170"/>
                            <pin id="175"/>
                            <pin id="159"/>
                            <pin id="213"/>
                            <pin id="154"/>
                            <pin id="234"/>
                            <pin id="199"/>
                            <pin id="142"/>
                            <pin id="141"/>
                            <pin id="200"/>
                            <pin id="194"/>
                            <pin id="152"/>
                            <pin id="216"/>
                            <pin id="144"/>
                            <pin id="203"/>
                            <pin id="146"/>
                            <pin id="126"/>
                            <pin id="131"/>
                            <pin id="217"/>
                            <pin id="168"/>
                            <pin id="198"/>
                            <pin id="153"/>
                            <pin id="124"/>
                            <pin id="80"/>
                            <pin id="81"/>
                            <pin id="125"/>
                            <pin id="53"/>
                            <pin id="104"/>
                            <pin id="54"/>
                            <pin id="60"/>
                            <pin id="37"/>
                            <pin id="109"/>
                            <pin id="49"/>
                            <pin id="75"/>
                            <pin id="34"/>
                            <pin id="33"/>
                            <pin id="39"/>
                            <pin id="29"/>
                            <pin id="28"/>
                            <pin id="64"/>
                            <pin id="94"/>
                            <pin id="35"/>
                            <pin id="92"/>
                            <pin id="87"/>
                            <pin id="149"/>
                            <pin id="300"/>
                            <pin id="85"/>
                            <pin id="44"/>
                            <pin id="339"/>
                            <pin id="72"/>
                            <pin id="77"/>
                            <pin id="90"/>
                            <pin id="38"/>
                            <pin id="89"/>
                            <pin id="40"/>
                            <pin id="71"/>
                            <pin id="51"/>
                            <pin id="99"/>
                            <pin id="41"/>
                            <pin id="102"/>
                            <pin id="43"/>
                            <pin id="58"/>
                            <pin id="93"/>
                            <pin id="114"/>
                            <pin id="57"/>
                            <pin id="91"/>
                            <pin id="66"/>
                            <pin id="70"/>
                            <pin id="123"/>
                            <pin id="65"/>
                            <pin id="310"/>
                            <pin id="157"/>
                            <pin id="129"/>
                            <pin id="136"/>
                            <pin id="118"/>
                            <pin id="116"/>
                            <pin id="324"/>
                            <pin id="103"/>
                            <pin id="76"/>
                            <pin id="50"/>
                            <pin id="67"/>
                            <pin id="84"/>
                            <pin id="32"/>
                            <pin id="110"/>
                            <pin id="106"/>
                            <pin id="30"/>
                            <pin id="82"/>
                            <pin id="119"/>
                            <pin id="78"/>
                            <pin id="52"/>
                            <pin id="299"/>
                            <pin id="79"/>
                            <pin id="42"/>
                            <pin id="86"/>
                            <pin id="62"/>
                            <pin id="83"/>
                            <pin id="97"/>
                            <pin id="96"/>
                            <pin id="147"/>
                            <pin id="113"/>
                            <pin id="95"/>
                            <pin id="74"/>
                        </flexcomp>
                    </body>

                    <body name="foot" pos="-0.00526 0 -0.30429">
                        <inertial pos="0 0 -0.03696" mass="0.31095" fullinertia="0.00047 0.00046 0.00078 0 0 0"/>
                        <joint axis="0 1 0" name="ankle_angle_l" pos="0 0 0" range="-0.9 0.9"/>
                        <geom mesh="foot" name="foot" type="mesh"/>
                        <site name="ankle_sensor" pos="0 0 0"/>
                    </body>
                </body>
            </body>
        </body>
    </worldbody>
</mujoco>