<mujoco model="phantom_barrutia">
    <option timestep=".0001"/>

    <compiler angle="radian" strippath="true" meshdir="meshes/Barrutia/"/>

    <visual>
        <map force="0.001"/>
        <scale framelength="0.1" framewidth="0.01"/>
        <global offheight="640"/>
    </visual>

    <asset>
        <texture name="skybox" type="skybox" builtin="flat" rgb1="0.8 0.8 0.8" rgb2="0.8 0.8 0.8" width="512" height="512"/>

        <material name="mat_bones" rgba="0.2 0.2 0.2 1"/>
        <material name="exosuit" rgba="0.2 0.2 0.2 0"/>

        <mesh file="Hip Fixture.STL" name="hip_fixture"/>
        <mesh file="Femur.STL" name="femur"/>
        <mesh file="Tibia.STL" name="tibia"/>
        <mesh file="Foot.STL" name="foot"/>
        <mesh file="Platform.STL" name="platform"/>
        <mesh file="ThighStrap.STL" name="thigh_strap"/>
        <mesh file="ShankStrap.STL" name="shank_strap"/>
        <meshfinder>
            <mesh name="ThighStrapCol" alias="thigh_strap_col" split="true"/>
            <mesh name="ShankStrapCol" alias="shank_strap_col" split="true"/>
        </meshfinder>
    </asset>

    <default>
        <default class="bones">
            <joint armature="0.01" limited="false"/>
            <geom margin="0.001" material="mat_bones" conaffinity="0" contype="0"/>
        </default>
        <default class="exosuit">
            <geom conaffinity="1" contype="1" material="exosuit"/>
        </default>
        <default class="flexbody">
            <joint armature="0" damping="0" limited="false"/>
        </default>
    </default>

    <equality>
        <weld body1="foot" body2="platform" torquescale="1000"/>
    </equality>

    <actuator>
        <position name="platform_act" kp="10000" kv="200" joint="platform_slide"/>
        <general name="clutch_spring" joint="shank_band_knee" gainprm="20 0" ctrlrange="-1 1"/>
    </actuator>

    <sensor>
        <force name="ankle_force" site="ankle_sensor"/>
        <jointpos joint="shank_band_knee" name="theta_exo"/>
    </sensor>

    <worldbody>
        <!-- <camera name="fixed_cam" mode="fixed" pos="0.628 -0.961 0.780" xyaxes="0.866 0.500 0.000 -0.171 0.296 0.940"/> -->
        <camera name="fixed_cam" mode="fixed" pos="0.991 0.629 0.640" xyaxes="-0.514 0.858 -0.000 -0.234 -0.140 0.962"/>
        <!-- <camera name="fixed_cam" mode="fixed" pos="-0.066 -0.097 0.523" xyaxes="0.705 -0.709 0.000 0.083 0.083 0.993"/> -->


        <body name="platform" pos="0 0 0" childclass="bones" mocap="false">
            <joint type="slide" axis="0 0 1" name="platform_slide" range="-2.5 2.5"/>
            <geom mesh="platform" name="platform" type="mesh" mass="1" pos="0.03835 0.07698 -0.01" quat="0.707107 0.707107 0 0"/>
        </body>

        <body name="hip_fixture" pos="0 0 0" childclass="bones">
            <inertial pos="0.03835 0.07698 0.67989" mass="0.13071" diaginertia="0.00006778 0.00006167 0.00008403" />
            <geom mesh="hip_fixture" name="hip_fixture" type="mesh"/>

            <body name="femur" pos="0.03835 0.07698 0.65793">
                <inertial pos="0.00457 0.01134 -0.14377" mass="0.24064" xyaxes="-0.11102 0.06309 0.99181 -0.33501 0.93720 -0.09711" diaginertia="0.00005 0.00247 0.00248"/>
                <joint axis="0 1 0" name="hip_flexion_l" pos="0 0 0" range="-0.523599 2.0944"/>
                <geom mesh="femur" name="femur" type="mesh"/>

                <body name="thigh" pos="0 0 0" childclass="flexbody">
                    <flexcomp type="gmsh" file="Thigh.msh" rgba=".9 .7 .0 .3" name="thigh" dim="2" mass="2.26449451">
                        <contact condim="3" solref="0.01 1" solimp=".95 .99 .0001" selfcollide="none"/>
                        <edge damping="1"/>
                        <elasticity young="6.6e4" poisson="0.48" damping="2.5e-5"/>
                        <pinmesh mesh="femur"/>
                    </flexcomp>
                </body>

                <body name="thigh_band" pos="0.00526 0 -0.29865" childclass="exosuit">
                    <joint axis="0 1 0" name="thigh_band_knee" pos="0 0 0"/>
                    <geom mesh="thigh_strap_col" name="thigh_band_col" type="mesh" pos="0 0 0" mass="1" euler="0 0 0"/>

                    <body name="thigh_band_vis" pos="0 0 0" childclass="bones">
                        <geom mesh="thigh_strap" name="thigh_band_vis" type="mesh" pos="0 0 0" mass="0.1" euler="0 0 0"/>
                    </body>

                    <body name="shank_band" pos="0 0 0">
                        <joint axis="0 1 0" name="shank_band_knee" pos="0 0 0"/>
                        <geom mesh="shank_strap_col" name="shank_band_col" type="mesh" pos="0 0 0" mass="1" euler="0 0 0"/>

                        <body name="shank_band_vis" pos="0 0 0" childclass="bones">
                            <geom mesh="shank_strap" name="shank_band_vis" type="mesh" pos="0 0 0" mass="0.1" euler="0 0 0"/>
                        </body>
                    </body>
                </body>

                <body name="tibia" pos="0.00526 0 -0.29865">
                    <inertial pos="0.00158 0.00259 -0.10784" mass="0.32564" fullinertia="0.00298 0.00298 0.00010 -0.00001 0.00012 -0.00001"/>
                    <joint axis="0 1 0" name="knee_angle_l" pos="0 0 0" range="0 3.0944"/>
                    <geom mesh="tibia" name="tibia" type="mesh"/>

                    <body name="shank" pos="0 0 0" childclass="flexbody">
                        <flexcomp type="gmsh" file="Shank.msh" rgba=".9 .7 .0 .3" name="l_shank" dim="2" mass="0.90204033">
                            <contact condim="3" solref="0.01 1" solimp=".95 .99 .0001" selfcollide="none"/>
                            <edge damping="1"/>
                            <elasticity young="6.6e4" poisson="0.48" damping="2.5e-5"/>
                            <pinmesh mesh="tibia"/>
                        </flexcomp>
                    </body>

                    <body name="foot" pos="-0.00526 0 -0.30429">
                        <inertial pos="0 0 -0.03696" mass="0.31095" fullinertia="0.00047 0.00046 0.00078 0 0 0"/>
                        <joint axis="0 1 0" name="ankle_angle_l" pos="0 0 0" range="-0.9 0.9"/>
                        <geom mesh="foot" name="foot" type="mesh"/>
                        <site name="ankle_sensor" pos="0 0 0"/>
                    </body>
                </body>
            </body>
        </body>
    </worldbody>
</mujoco>